Workbook

Sheet Summary_Store
A1: No. | B1: Category | C1: Qty | D1: Notes | E1: HCM | F1: South stores (other than HCM) | G1: HN | H1: North stores (other than HN)
A2: 1 | B2: Number of active stores | C2: =COUNTIFS(Store_Info_VN!D:D,"Open",Store_Info_VN!K:K,"Store") + COUNTIFS(Store_Info_VN!D:D,"Open",Store_Info_VN!K:K,"Multi PC") + COUNTIFS(Store_Info_VN!D:D,"Open",Store_Info_VN!K:K,"Mono") + COUNTIFS(Store_Info_VN!D:D,"Open",Store_Info_VN!K:K,"SIS") -> 1 | E2: =COUNTIFS(Store_Info_VN!D:D,"Open",Store_Info_VN!K:K,"Store",Store_Info_VN!F:F,"Ho Chi Minh City") + COUNTIFS(Store_Info_VN!D:D,"Open",Store_Info_VN!K:K,"Mono",Store_Info_VN!F:F,"Ho Chi Minh City") + COUNTIFS(Store_Info_VN!D:D,"Open",Store_Info_VN!K:K,"SIS",Store_Info_VN!F:F,"Ho Chi Minh City") -> 1 | F2: =(COUNTIFS(Store_Info_VN!D:D,"Open",Store_Info_VN!K:K,"Store",Store_Info_VN!G:G,"South") + COUNTIFS(Store_Info_VN!D:D,"Open",Store_Info_VN!K:K,"Mono",Store_Info_VN!G:G,"South") + COUNTIFS(Store_Info_VN!D:D,"Open",Store_Info_VN!K:K,"SIS",Store_Info_VN!G:G,"South"))-E2 -> -1 | G2: =COUNTIFS(Store_Info_VN!D:D,"Open",Store_Info_VN!K:K,"Store",Store_Info_VN!F:F,"Ha Noi") + COUNTIFS(Store_Info_VN!D:D,"Open",Store_Info_VN!K:K,"Mono",Store_Info_VN!F:F,"Ha Noi") + COUNTIFS(Store_Info_VN!D:D,"Open",Store_Info_VN!K:K,"SIS",Store_Info_VN!F:F,"Ha Noi") -> 0 | H2: =(COUNTIFS(Store_Info_VN!D:D,"Open",Store_Info_VN!K:K,"Store",Store_Info_VN!G:G,"North") + COUNTIFS(Store_Info_VN!D:D,"Open",Store_Info_VN!K:K,"Mono",Store_Info_VN!G:G,"North") + COUNTIFS(Store_Info_VN!D:D,"Open",Store_Info_VN!K:K,"SIS",Store_Info_VN!G:G,"North"))-G2 -> 1
A3: =A2+1 -> 2 | B3: Number of active bazaar | C3: =COUNTIFS(Store_Info_VN!D:D,"Open",Store_Info_VN!K:K,"Bazaar") -> 14
A4: =A3+1 -> 3 | B4: Number of active events, private sales | C4: {=SUM(COUNTIFS(Store_Info_VN!D:D,"Open",Store_Info_VN!K:K,{"EVENT","PRIVATE SALE"}))} -> 1
A5: =A4+1 -> 4 | B5: Total (active) | C5: =SUM(C2:C4) -> 16
A6: =A5+1 -> 5 | B6: Existing stores that need to deploy FG-40F | C6: =COUNTIFS(Store_Info_VN!D:D,"Open",Store_Info_VN!L:L,"Need to deploy (FG-40F)") -> 27
A7: =A6+1 -> 6 | B7: Existing stores that need to deploy FG-60F | C7: =COUNTIFS(Store_Info_VN!L:L,"Need to deploy (FG-60F)") -> 0
A8: =A7+1 -> 7 | B8: Extra Details - Number of active Mono stores | C8: =COUNTIFS(Store_Info_VN!D:D,"Open",Store_Info_VN!K:K,"Store") + COUNTIFS(Store_Info_VN!D:D,"Open",Store_Info_VN!K:K,"Mono") -> 0
A9: =A8+1 -> 8 | B9: Extra Details - Number of active SIS stores | C9: =COUNTIFS(Store_Info_VN!D:D,"Open",Store_Info_VN!K:K,"Store") + COUNTIFS(Store_Info_VN!D:D,"Open",Store_Info_VN!K:K,"SIS") -> 1
A10: =A9+1 -> 9 | B10: Stores enabled O2O | C10: =COUNTIFS(Store_Info_VN!D:D,"Open",Store_Info_VN!P:P,"Yes") -> 10

Sheet Summary_Endpoint
A1: Category | B1: Total
A2: VN Office Computers | B2: =COUNTIFS(Asset_Office!J:J,"Laptop")+COUNTIFS(Asset_Office!J:J,"Desktop") -> 103
A3: Completed for VN Office Computers | B3: =COUNTIF(Asset_Office!Y:Y,"DONE") -> 90
A4: Remaining VN Office Computers to unjoin existing domain & change hostname & use OneDrive to store data | B4: =B2-B3 -> 13
A5: VN Office Bazaar Computers | B5: 5
A6: Completed for VN Office Bazaar Computers | B6: 0
A7: Remaining VN Office Bazaar Computers to unjoin existing domain & change hostname & use OneDrive to store data | B7: =B5-B6 -> 5
A8: Cambodia Office Computers | B8: 6
A9: Completed for Cambodia Office Computers | B9: 6
A10: Remaining Cambodia Office Computers to unjoin existing domain & change hostname & use OneDrive to store data | B10: =B8-B9 -> 0

Sheet Asset_Store
A1: No. | B1: Asset ID | C1: Status (formula) | D1: Assigned To (formula) | E1: Description (formula) | F1: Location | G1: Asset Description (formula) | H1: Qty | I1: Asset Type (formula) | J1: Brand | K1: Model | L1: Additional Specs | M1: S/N | N1: RAM (GB) | O1: Hard Disk (GB) | P1: Hard Disk Type | Q1: CPU | R1: Purchase Date | S1: Vendor/Supplier | T1: Note | U1: Assignment History | V1: Old Hostname | W1: Hostname | X1: AD unjoin, change hostname | Y1: Status BIGFIX | Z1: STATUS Crowdstrike | AA1: JOIN DOMAIN
B2: Template | E2: =VLOOKUP(D2,Store_Info_VN!B:P,2,0) -> #N/A | G2: =I2&" "&J2&" "&K2
A3: 1 | B3: 22VN00110001 | C3: Available | D3: KN01 | E3: =VLOOKUP(D3,Store_Info_VN!B:P,2,0) -> BIRKENSTOCK ESTELLA | F3: Store | G3: =I3&" "&J3&" "&K3 -> Desktop HP ProDesk 400 G4 DM | H3: 1 | I3: Desktop | J3: HP | K3: ProDesk 400 G4 DM | M3: 8CC90102Q1 | N3: 8 | O3: 500 | P3: HDD | Q3: 2100 MHz Core i5-8500T | V3: KN01-ADMIN | W3: KN01-ADMIN | X3: DONE | Y3: DONE | Z3: DONE
A4: =A3+1 -> 2 | B4: 22VN00110001 | C4: In Use | D4: VA14 | E4: New Balance Vincom Dong Khoi | F4: Store | G4: HP ProDesk 400 G3 DM | H4: 1 | I4: Desktop | J4: HP | K4: ProDesk 400 G3 DM | M4: 8CG8105N35 | V4: KN01
A5: =A4+1 -> 3 | B5: 22VN00110002 | C5: In Use | D5: VA16 | E5: New Balance Outlet Quang Trung | F5: Store | G5: HP ProDesk 400 G3 DM | H5: 1 | I5: Desktop | J5: HP | K5: ProDesk 400 G3 DM | M5: 8CG8105N1T
A6: 2 | B6: 22VN00110003 | C6: Available | D6: HR Intern | E6: PLANET SPORTS VINCOM DONG KHOI (closed) | F6: Store | G6: =I6&" "&J6&" "&K6 -> Desktop HP ProDesk 400 G4 DM | H6: 1 | I6: Desktop | J6: HP | K6: ProDesk 400 G4 DM | M6: 8CG8105MSL | N6: 8 | O6: 500 | P6: SSD | Q6: 2700 MHz Core i5-7500T | T6: đã thu hồi | U6: IT BACKUP đang cấp Nguyễn Bảo Du InterHR | V6: PO02-Server | W6: PO02-Server | Y6: DONE | Z6: DONE
A7: 5 | B7: 22VN00110006 | C7: Available | D7: VA02 | E7: =VLOOKUP(D7,Store_Info_VN!B:P,2,0) -> NEW BALANCE TAKASHIMAYA | F7: Store | G7: =I7&" "&J7&" "&K7 -> Laptop HP ProBook 440 14 inch G9 Notebook PC | H7: 1 | I7: Laptop | J7: HP | K7: ProBook 440 14 inch G9 Notebook PC | M7: 5CD250F9ZW | N7: 16 | O7: 487749 | P7: SSD | Q7: 2500 MHz 12th Gen Intel Core i5-1235U | T7: Cần tìm lại file scan | V7: VA02-ADMIN | W7: VA02-ADMIN | Y7: DONE | Z7: DONE
A8: 6 | C8: Available | D8: VA02 | E8: =VLOOKUP(D8,Store_Info_VN!B:P,2,0) -> NEW BALANCE TAKASHIMAYA | F8: Store | G8: =I8&" "&J8&" "&K8 -> Bill Printer Epson TM-T82III | H8: 1 | I8: Bill Printer | J8: Epson | K8: TM-T82III | M8: G22EB4602
A9: 7 | C9: Available | D9: VA02 | E9: =VLOOKUP(D9,Store_Info_VN!B:P,2,0) -> NEW BALANCE TAKASHIMAYA | F9: Store | G9: =I9&" "&J9&" "&K9 -> Scanner Datalogic QW2100 | H9: 1 | I9: Scanner | J9: Datalogic | K9: QW2100 | M9: 5CD250F9ZW
A10: 8 | C10: Available | D10: VA02 | E10: =VLOOKUP(D10,Store_Info_VN!B:P,2,0) -> NEW BALANCE TAKASHIMAYA | F10: Store | G10: =I10&" "&J10&" "&K10 -> A4 Printer Canon LBP 2900 | H10: 1 | I10: A4 Printer | J10: Canon | K10: LBP 2900 | M10: NMYA783802
A11: 9 | C11: Available | D11: VA02 | E11: =VLOOKUP(D11,Store_Info_VN!B:P,2,0) -> NEW BALANCE TAKASHIMAYA | F11: Store | G11: =I11&" "&J11&" "&K11 -> USB Kingston 32GB | H11: 1 | I11: USB | J11: Kingston | K11: 32GB
A12: 10 | B12: 22VN00110007 | C12: Available | D12: VA10 | E12: =VLOOKUP(D12,Store_Info_VN!B:P,2,0) -> NEW BALANCE LOTTE HA NOI DEPARTMENT | F12: Store | G12: ư/' | H12: 1 | I12: Laptop | J12: HP | K12: ProBook 440 14 inch G9 Notebook PC | M12: 5CD250F9QZ | N12: 16 | O12: 487757 | P12: SSD | Q12: 2500 MHz 12th Gen Intel Core i5-1235U | V12: VA10-ADMIN | W12: VA10-ADMIN | Y12: DONE | Z12: DONE
A13: 11 | C13: Available | D13: VA10 | E13: =VLOOKUP(D13,Store_Info_VN!B:P,2,0) -> NEW BALANCE LOTTE HA NOI DEPARTMENT | F13: Store | G13: =I13&" "&J13&" "&K13 -> Bill Printer Epson TM-T82III | H13: 1 | I13: Bill Printer | J13: Epson | K13: TM-T82III | M13: X7B9022786
A14: 12 | C14: Available | D14: VA10 | E14: =VLOOKUP(D14,Store_Info_VN!B:P,2,0) -> NEW BALANCE LOTTE HA NOI DEPARTMENT | F14: Store | G14: =I14&" "&J14&" "&K14 -> Scanner Datalogic QW2100 | H14: 1 | I14: Scanner | J14: Datalogic | K14: QW2100 | M14: G22F27244
A15: 13 | C15: Available | D15: VA10 | E15: =VLOOKUP(D15,Store_Info_VN!B:P,2,0) -> NEW BALANCE LOTTE HA NOI DEPARTMENT | F15: Store | G15: =I15&" "&J15&" "&K15 -> A4 Printer Canon LBP 2900 | H15: 1 | I15: A4 Printer | J15: Canon | K15: LBP 2900 | M15: NMYA782038
A16: 14 | C16: Available | D16: VA10 | E16: =VLOOKUP(D16,Store_Info_VN!B:P,2,0) -> NEW BALANCE LOTTE HA NOI DEPARTMENT | F16: Store | G16: =I16&" "&J16&" "&K16 -> USB Kingston | H16: 2 | I16: USB | J16: Kingston
A17: 15 | C17: Available | D17: VA10 | E17: =VLOOKUP(D17,Store_Info_VN!B:P,2,0) -> NEW BALANCE LOTTE HA NOI DEPARTMENT | F17: Store | G17: =I17&" "&J17&" "&K17 -> Mouse HP | H17: 1 | I17: Mouse | J17: HP
A18: 16 | C18: Available | D18: VC01 | E18: =VLOOKUP(D18,Store_Info_VN!B:P,2,0) -> CHAMPION VINCOM DONG KHOI | F18: Store | G18: =I18&" "&J18&" "&K18 -> Monitor HP V190 | H18: 1 | I18: Monitor | J18: HP | K18: V190 | M18: 1CR82307LJ | U18: Trước đó dùng cho VC01 - CHAMPION VINCOM DONG KHOI
A19: 17 | C19: Available | D19: VC01 | E19: =VLOOKUP(D19,Store_Info_VN!B:P,2,0) -> CHAMPION VINCOM DONG KHOI | F19: Store | G19: =I19&" "&J19&" "&K19 -> Bill Printer Epson TM-T82II | H19: 1 | I19: Bill Printer | J19: Epson | K19: TM-T82II | M19: TCCY014794 | U19: Trước đó dùng cho VC01 - CHAMPION VINCOM DONG KHOI
A20: 18 | C20: Available | D20: VR05 | E20: =VLOOKUP(D20,Store_Info_VN!B:P,2,0) -> ROOKIE LOTTE HA NOI DEPARTMENT | F20: Store | G20: =I20&" "&J20&" "&K20 -> Scanner Datalogic QW2100 | H20: 1 | I20: Scanner | J20: Datalogic | K20: QW2100 | M20: G18C39492 | U20: - Trước đó dùng cho VC01 - CHAMPION VINCOM DONG KHOI - Điều chuyển đến VR05
A21: 19 | C21: Available | D21: VC01 | E21: =VLOOKUP(D21,Store_Info_VN!B:P,2,0) -> CHAMPION VINCOM DONG KHOI | F21: Store | G21: =I21&" "&J21&" "&K21 -> Pole Display HP LD220 | H21: 1 | I21: Pole Display | J21: HP | K21: LD220 | M21: 2TD843AAA0 | U21: Trước đó dùng cho VC01 - CHAMPION VINCOM DONG KHOI
A22: 20 | C22: Available | D22: VC01 | E22: =VLOOKUP(D22,Store_Info_VN!B:P,2,0) -> CHAMPION VINCOM DONG KHOI | F22: Store | G22: =I22&" "&J22&" "&K22 | H22: 1 | U22: Trước đó dùng cho VC01 - CHAMPION VINCOM DONG KHOI
A23: 21 | C23: Available | D23: VC01 | E23: =VLOOKUP(D23,Store_Info_VN!B:P,2,0) -> CHAMPION VINCOM DONG KHOI | F23: Store | G23: =I23&" "&J23&" "&K23 | H23: 1 | U23: Trước đó dùng cho VC01 - CHAMPION VINCOM DONG KHOI
A24: 22
A25: 23 | B25: 22VN00000005 | C25: In Use | D25: VN03 | E25: VN03- CONVERSE TAKASHIMAYA | G25: Latitude 3520 | H25: STORE | I25: Dell | J25: Dell | K25: Latitude 3520 | M25: 8P9VKG3 | N25: 8 | O25: 256 | P25: SSD | Q25: 2200 MHz 11th Gen Intel Core i3-1115G4 @ 3.00GHz | T25: BÀN GIAO NGÀY 19-02-2024 CHO STORE CONVERSE TAKASHIMAYA (VN03) | U25: trước đây là laptop cũ của Diễm Quỳnh Accounting, ĐÃ SETUP CHO VN03 (CONVERSE TAKASHIMAYA) | W25: MMA-LAP-0005 | X25: DONE | Y25: DONE | Z25: DONE | AA25: DONE
A26: 24 | C26: Available | D26: VI02 | E26: =VLOOKUP(D26,Store_Info_VN!B:P,2,0) -> SMIGGLE TAKASHIMAYA | F26: Store | G26: =I26&" "&J26&" "&K26 -> Bill Printer Epson TM-T82III | H26: 1 | I26: Bill Printer | J26: Epson | K26: TM-T82III | M26: TCCY011121
A27: 25 | C27: Available | D27: VI02 | E27: =VLOOKUP(D27,Store_Info_VN!B:P,2,0) -> SMIGGLE TAKASHIMAYA | F27: Store | G27: =I27&" "&J27&" "&K27 -> Scanner Datalogic QW2100 | H27: 1 | I27: Scanner | J27: Datalogic | K27: QW2100 | M27: G14MA2902 | T27: THIẾU bbbg máy scan
A28: 3 | B28: 22VN00110004 | C28: In Use | D28: VA05 | E28: NEW BALANCE VINCOM THAO DIEN | F28: Store | G28: =I28&" "&J28&" "&K28 -> Desktop HP ProDesk 400 G4 DM | H28: 1 | I28: Desktop | J28: HP | K28: ProDesk 400 G4 DM | M28: 8CG8105MTN | N28: 8 | O28: 500 | P28: HDD | Q28: 2700 MHz Core i5-7500T | T28: đã thu hồi | U28: IT BACKUP | V28: PO02-POS1 | W28: PO02-POS1 | Y28: DONE | Z28: DONE
A29: 27 | C29: In Use | D29: VA03 | E29: =VLOOKUP(D29,Store_Info_VN!B:P,2,0) -> NEW BALANCE AEON HAI PHONG | F29: Store | G29: =I29&" "&J29&" "&K29 -> Monitor HP V190 | H29: 1 | I29: Monitor | J29: HP | K29: V190 | M29: 1CR82307DL | U29: - Trước đó dùng cho CHAMPION AEON HAI PHONG (VC03)
A30: 28 | C30: In Use | D30: VA03 | E30: =VLOOKUP(D30,Store_Info_VN!B:P,2,0) -> NEW BALANCE AEON HAI PHONG | F30: Store | G30: =I30&" "&J30&" "&K30 -> Bill Printer Epson TM-T82II | H30: 1 | I30: Bill Printer | J30: Epson | K30: TM-T82II | M30: TCEY007587 | U30: - Trước đó dùng cho CHAMPION AEON HAI PHONG (VC03)
A31: 29 | C31: In Use | D31: VA03 | E31: =VLOOKUP(D31,Store_Info_VN!B:P,2,0) -> NEW BALANCE AEON HAI PHONG | F31: Store | G31: =I31&" "&J31&" "&K31 -> Scanner Datalogic QW2100 | H31: 1 | I31: Scanner | J31: Datalogic | K31: QW2100 | M31: G20I34943 | U31: - Trước đó dùng cho CHAMPION AEON HAI PHONG (VC03)
A32: 30 | C32: In Use | D32: VA03 | E32: =VLOOKUP(D32,Store_Info_VN!B:P,2,0) -> NEW BALANCE AEON HAI PHONG | F32: Store | G32: =I32&" "&J32&" "&K32 -> Pole Display Topcash AL-CD1 | H32: 1 | I32: Pole Display | J32: Topcash | K32: AL-CD1 | M32: ALCD20110003 | U32: - Trước đó dùng cho CHAMPION AEON HAI PHONG (VC03)
A33: 31 | C33: Available | D33: IT | E33: Thu hồi từ New Balance Aeon Hai Phong (VA03) | F33: Store | G33: =I33&" "&J33&" "&K33 -> Cash Drawer Poscom 410 | H33: 1 | I33: Cash Drawer | J33: Poscom | K33: 410 | M33: 2020092549 | U33: - Trước đó dùng cho CHAMPION AEON HAI PHONG (VC03)
A34: 32 | C34: In Use | D34: VA03 | E34: =VLOOKUP(D34,Store_Info_VN!B:P,2,0) -> NEW BALANCE AEON HAI PHONG | F34: Store | G34: =I34&" "&J34&" "&K34 -> A4 Printer Canon LBP 2900 | H34: 1 | I34: A4 Printer | J34: Canon | K34: LBP 2900 | M34: NMYA467017 | U34: - Trước đó dùng cho CHAMPION AEON HAI PHONG (VC03)
A35: 33 | B35: 22VN00110011 | C35: In Use | D35: VA23 | E35: =VLOOKUP(D35,Store_Info_VN!B:P,2,0) -> New Balance Lotte Lieu Giai | F35: Store | G35: =I35&" "&J35&" "&K35 -> Laptop Dell Inspiron 3505 | H35: 1 | I35: Laptop | J35: Dell | K35: Inspiron 3505 | M35: HRBPK73 | N35: 6 | O35: 235 | P35: SSD | Q35: 2600 MHz Ryzen 3 3250U with Radeon Graphics | V35: VC04-ADMIN | W35: VC04-ADMIN | Y35: DONE | Z35: DONE
A36: 34 | C36: In Use | D36: VA23 | E36: =VLOOKUP(D36,Store_Info_VN!B:P,2,0) -> New Balance Lotte Lieu Giai | F36: Store | G36: =I36&" "&J36&" "&K36 -> Bill Printer Epson TM-T82III | H36: 1 | I36: Bill Printer | J36: Epson | K36: TM-T82III | M36: X7BA000883
A37: 35 | C37: In Use | D37: VA23 | E37: =VLOOKUP(D37,Store_Info_VN!B:P,2,0) -> New Balance Lotte Lieu Giai | F37: Store | G37: =I37&" "&J37&" "&K37 -> Scanner Datalogic QW2100 | H37: 1 | I37: Scanner | J37: Datalogic | K37: QW2100 | M37: G20L70107 | T37: G20L70107 - IT BACKUP đem đổi mới cho VC04 G22F27150 trước đó cấp cho store bị hư, đã thu hồi
A38: 36 | C38: In Use | D38: VA23 | E38: =VLOOKUP(D38,Store_Info_VN!B:P,2,0) -> New Balance Lotte Lieu Giai | F38: Store | G38: =I38&" "&J38&" "&K38 -> Network Switch Mercusys | H38: 1 | I38: Network Switch | J38: Mercusys | L38: 8 Port | M38: 2201552001975 | T38: STORE LÀM MẤT
A39: 37 | C39: In Use | D39: VA23 | E39: =VLOOKUP(D39,Store_Info_VN!B:P,2,0) -> New Balance Lotte Lieu Giai | F39: Store | G39: =I39&" "&J39&" "&K39 -> A4 Printer Canon LBP 3300 | H39: 1 | I39: A4 Printer | J39: Canon | K39: LBP 3300 | M39: NMYA467026
A40: 4 | B40: 22VN00110005 | C40: Spare | D40: IT BACKUP | E40: PLANET SPORTS VINCOM DONG KHOI (closed) | F40: Store | G40: =I40&" "&J40&" "&K40 -> Desktop HP ProDesk 400 G4 DM | H40: 1 | I40: Desktop | J40: HP | K40: ProDesk 400 G4 DM | M40: 8CG8105MSN | N40: 8 | O40: 500 | P40: HDD | Q40: 2700 MHz Core i5-7500T | T40: đã thu hồi | U40: IT BACKUP | V40: PO02-POS2 | W40: PO02-POS2 | Y40: DONE | Z40: DONE
...

Sheet Asset_Office
A1: No. | B1: Asset ID | C1: Status (formula) | D1: Assigned To (formula) | E1: Description (formula) | F1: Hostname | G1: AD User (formula) | H1: Location | I1: Asset Name (formula) | J1: Asset Type (formula) | K1: Brand | L1: Model | M1: S/N | N1: RAM (GB) | O1: Hard Disk (GB) | P1: Hard Disk Type | Q1: CPU | R1: Purchase Date | S1: Vendor/Supplier | T1: Note | V1: Assignment History | W1: USB TOKEN | X1: Old Hostname | Y1: AD unjoin, change hostname | Z1: PASTE ASSET ID | AA1: Status BIGFIX | AB1: STATUS Crowdstrike | AC1: STATUS JOIN DOMAIN
A2: 1 | B2: 22VN00000001 | C2: In Use | D2: =VLOOKUP(B2,VN_Emails!B:H,4,0) -> Tiet Nha Phung | E2: =VLOOKUP(B2,VN_Emails!B:H,7,0) -> Brand Manager (Converse) | F2: AMMAVNAMC000001 | G2: =SUBSTITUTE(VLOOKUP(B2,VN_Emails!B:H,2,0),"@mapactive.vn","") -> phung.tietnha | H2: Office | I2: =J2&" "&K2&" "&L2 -> Laptop HP Latitude 7420 | J2: Laptop | K2: HP | L2: Latitude 7420 | M2: DVV62J3 | N2: 16 | O2: 512 | P2: SSD | Q2: 1700 MHz 11th Gen Intel Core i7-1165G7 @ 2.80GHz | X2: MMA-LAP-0001 | Y2: DONE | Z2: DONE | AA2: DONE | AB2: DONE | AC2: Created it.active local account
A3: =A2+1 -> 2 | B3: 22VN00000002 | C3: In Use | D3: =VLOOKUP(B3,VN_Emails!B:H,4,0) -> Doan Thien Ho An | E3: =VLOOKUP(B3,VN_Emails!B:H,7,0) -> Digital Marketing Manager | F3: AMMAVNACC000002 | G3: =SUBSTITUTE(VLOOKUP(B3,VN_Emails!B:H,2,0),"@mapactive.vn","") -> Doan.An | H3: Office | I3: =J3&" "&K3&" "&L3 -> Laptop Dell Latitude 7420 | J3: Laptop | K3: Dell | L3: Latitude 7420 | M3: 124N1J3 | N3: 16 | O3: 512 | P3: SSD | Q3: 1700 MHz 11th Gen Intel Core i7-1165G7 @ 2.80GHz | V3: DANG BH LAPTOP KO LÊN NGUỒN | X3: MMA-LAP-0002 | Y3: Need to do both | Z3: DONE | AA3: DONE | AB3: DONE
A4: =A3+1 -> 3 | B4: 22VN00000003 | C4: Available | D4: =VLOOKUP(B4,VN_Emails!B:H,4,0) -> #N/A | E4: =VLOOKUP(B4,VN_Emails!B:H,7,0) -> #N/A | F4: AMMAVNACC000003 | G4: #N/A | H4: Office | I4: =J4&" "&K4&" "&L4 -> Laptop Dell Latitude 5420 | J4: Laptop | K4: Dell | L4: Latitude 5420 | M4: 1Z8DZH3 | N4: 16 | O4: 512 | P4: SSD | Q4: 1400 MHz 11th Gen Intel Core i5-1135G7 @ 2.40GHz | T4: UPDATE NEW SSD 500GB SAMSUNG | V4: đã bh ssd vs CMCSG samsung 500GB lưu kho IT Lấy ổ cứng SSD đã bảo hành của chị Mai (M.2 SSD - Model A60 - 512GB - S/N: 23027592-050170B) để thay vào laptop Dell Latitude 7420 của chị Uyên Máy cũ chị Maya đã thu hồi 22/01/2024 , Hiếu IT đang giữ | W4: use USB token | X4: MMA-LAP-0003 | Y4: DONE | Z4: DONE | AA4: DONE | AB4: DONE
A5: =A4+1 -> 4 | B5: 22VN00000004 | C5: In Use | D5: =VLOOKUP(B5,VN_Emails!B:H,4,0) -> Nguyen Thi Thuy Mong | E5: =VLOOKUP(B5,VN_Emails!B:H,7,0) -> Senior Brand Marketing Manager | F5: AMMAVNACC000004 | G5: =SUBSTITUTE(VLOOKUP(B5,VN_Emails!B:H,2,0),"@mapactive.vn","") -> mong.nguyenthithuy | H5: Office | I5: =J5&" "&K5&" "&L5 -> Laptop Dell Latitude 5430 | J5: Laptop | K5: Dell | L5: Latitude 5430 | M5: 42X2SQ3 | N5: 8 | O5: 512 | P5: SSD | Q5: 2500 MHz 12th Gen Intel Core i5-1235U | V5: Máy của Danh thỉnh thoảng không lên màn hình | X5: MMA-LAP-0004 | Y5: DONE | Z5: DONE | AA5: DONE | AB5: DONE
A6: =A5+1 -> 5 | B6: 22VN00000006 | C6: In Use | D6: =VLOOKUP(B6,VN_Emails!B:H,4,0) -> Le Hong Bao Chau | E6: =VLOOKUP(B6,VN_Emails!B:H,7,0) -> Marketing Admin | F6: AMMAVNACC000006 | G6: =SUBSTITUTE(VLOOKUP(B6,VN_Emails!B:H,2,0),"@mapactive.vn","") -> chau.lehongbao | H6: Office | I6: =J6&" "&K6&" "&L6 -> Laptop Dell Latitude 3520 | J6: Laptop | K6: Dell | L6: Latitude 3520 | M6: 5R4JGL3 | N6: 8 | O6: 256 | P6: SSD | Q6: 1400 MHz 11th Gen Intel Core i5-1135G7 @ 2.40GHz | V6: old laptop Nguyen Hoang Anh Thy Accounting, IT thu hồi 21-02-2024 | X6: AMMAVNACC000006 | Y6: DONE | Z6: DONE | AA6: DONE | AB6: DONE
A7: =A6+1 -> 6 | B7: 22VN00000007 | C7: In Use | D7: =VLOOKUP(B7,VN_Emails!B:H,4,0) -> #N/A | E7: =VLOOKUP(B7,VN_Emails!B:H,7,0) -> #N/A | F7: AMMAVNACCC000007 | G7: =SUBSTITUTE(VLOOKUP(B7,VN_Emails!B:H,2,0),"@mapactive.vn","") -> #N/A | H7: Office | I7: =J7&" "&K7&" "&L7 -> Laptop Dell Latitude 3420 | J7: Laptop | K7: Dell | L7: Latitude 3420 | M7: 65G48S3 | N7: 16 | O7: 512 | P7: SSD | Q7: 1400 MHz 11th Gen Intel Core i5-1135G7 @ 2.40GHz | X7: MMA-LAP-0007 | Y7: DONE | Z7: DONE | AA7: DONE | AB7: DONE
A8: =A7+1 -> 7 | B8: 22VN00000008 | C8: Available | D8: =VLOOKUP(B8,VN_Emails!B:H,4,0) -> #N/A | E8: =VLOOKUP(B8,VN_Emails!B:H,7,0) -> #N/A | F8: AMMAVNACC000008 | G8: =SUBSTITUTE(VLOOKUP(B8,VN_Emails!B:H,2,0),"@mapactive.vn","") -> #N/A | H8: Office | I8: =J8&" "&K8&" "&L8 -> Laptop Dell Latitude 3520 | J8: Laptop | K8: Dell | L8: Latitude 3520 | M8: 2P8VKG3 | N8: 8 | O8: 512 | P8: SSD | Q8: 1400 MHz 11th Gen Intel Core i3-1135G7 @ 2.40GHz | W8: use USB token | X8: MMA-LAP-0008 | Y8: DONE | Z8: DONE | AA8: DONE | AB8: DONE
A9: =A8+1 -> 8 | B9: 22VN00000009 | C9: In Use | D9: =VLOOKUP(B9,VN_Emails!B:H,4,0) -> Le Cam Linh | E9: =VLOOKUP(B9,VN_Emails!B:H,7,0) -> Shipping Supervisor | F9: AMMAVNLOC000009 | G9: =SUBSTITUTE(VLOOKUP(B9,VN_Emails!B:H,2,0),"@mapactive.vn","") -> linh.lecam | H9: Office | I9: =J9&" "&K9&" "&L9 -> Laptop Dell Latitude 5430 | J9: Laptop | K9: Dell | L9: Latitude 5430 | M9: 1583SQ3 | N9: 20 | O9: 512 | P9: SSD | Q9: 2500 MHz 12th Gen Intel Core i5-1235U | X9: MMA-LAP-0009 | Y9: DONE | AA9: DONE | AB9: DONE
A10: =A9+1 -> 9 | B10: 22VN00000010 | C10: Available | D10: =VLOOKUP(B10,VN_Emails!B:H,4,0) -> #N/A | E10: =VLOOKUP(B10,VN_Emails!B:H,7,0) -> #N/A | F10: AMMAVNROC000010 | G10: =SUBSTITUTE(VLOOKUP(B10,VN_Emails!B:H,2,0),"@mapactive.vn","") -> #N/A | H10: Office | I10: =J10&" "&K10&" "&L10 -> Laptop Dell Latitude 3520 | J10: Laptop | K10: Dell | L10: Latitude 3520 | M10: 4Q9VKG3 | N10: 8 | O10: 256 | P10: SSD | Q10: 2200 MHz 11th Gen Intel Core i3-1115G4 @ 3.00GHz | V10: Máy Mỹ TRang cũ | X10: MMA-LAP-0010 | Y10: DONE | Z10: DONE | AA10: DONE | AB10: DONE
A11: =A10+1 -> 10 | B11: 22VN00000011 | C11: Available | D11: =VLOOKUP(B11,VN_Emails!B:H,4,0) -> #N/A | E11: =VLOOKUP(B11,VN_Emails!B:H,7,0) -> #N/A | F11: AMMAVNMDC000011 | G11: =SUBSTITUTE(VLOOKUP(B11,VN_Emails!B:H,2,0),"@mapactive.vn","") -> #N/A | H11: Office | I11: =J11&" "&K11&" "&L11 -> Laptop Dell Latitude 5430 | J11: Laptop | K11: Dell | L11: Latitude 5430 | M11: F083SQ3 | N11: 16 | O11: 512 | P11: SSD | Q11: 2500 MHz 12th Gen Intel Core i5-1235U | V11: SỬ DỤNG MÁY 5430 CỦA LƯU GIANG CẨM VÂN(VICKY) ĐÃ THAY SSD BỊ HƯ TỪ CMC (LẦN 1) CHỜ CỨU DATA TỪ SÓNG NAM SAU ĐÓ BH SSD VS CMC(SAU TẾT) CMC ĐÃ GỬI LẠI SSD MỚI NGÀY 08/03/2024 | X11: MMA-LAP-0011 | Y11: DONE | Z11: DONE | AA11: DONE | AB11: DONE
A12: =A11+1 -> 11 | B12: 22VN00000012 | C12: Available | D12: =VLOOKUP(B12,VN_Emails!B:H,4,0) -> #N/A | E12: =VLOOKUP(B12,VN_Emails!B:H,7,0) -> #N/A | G12: =SUBSTITUTE(VLOOKUP(B12,VN_Emails!B:H,2,0),"@mapactive.vn","") -> #N/A | H12: Office | I12: =J12&" "&K12&" "&L12 -> Laptop Dell Latitude 3520 | J12: Laptop | K12: Dell | L12: Latitude 3520 | M12: BR9VKG3 | N12: 8 | O12: 256 | P12: SSD | Q12: 2200 MHz 11th Gen Intel Core i3-1115G4 @ 3.00GHz | T12: Máy lỗi loa user binh.ngotieu 16/05/24, Cấp tạm cho Lan Vy Cấp ZV16 26/08/2024 | X12: MMA-LAP-0012 | Y12: DONE | Z12: DONE | AA12: DONE | AB12: DONE
A13: =A12+1 -> 12 | B13: 22VN00000013 | C13: In Use | D13: =VLOOKUP(B13,VN_Emails!B:H,4,0) -> Tran Thi Yen Nhi | E13: =VLOOKUP(B13,VN_Emails!B:H,7,0) -> Payroll & Em. Servieces Executive | F13: AMMAVNHRC000013 | G13: =SUBSTITUTE(VLOOKUP(B13,VN_Emails!B:H,2,0),"@mapactive.vn","") -> nhi.tranthiyen | H13: Office | I13: =J13&" "&K13&" "&L13 -> Laptop HP Pavilion 15-eg0xxx | J13: Laptop | K13: HP | L13: Pavilion 15-eg0xxx | M13: 5CD1294NHX | N13: 8 | O13: 512 | P13: SSD | Q13: 2400 MHz 11th Gen Intel Core i5-1135G7 @ 2.40GHz | W13: use USB token | X13: MMA-LAP-0013 | Y13: DONE | Z13: DONE | AA13: DONE | AB13: DONE
A14: =A13+1 -> 13 | B14: 22VN00000014 | C14: In Use | D14: =VLOOKUP(B14,VN_Emails!B:H,4,0) -> Ni Ksormahhko | E14: =VLOOKUP(B14,VN_Emails!B:H,7,0) -> Procurement Executive | F14: AMMAVNPUC000014 | G14: =SUBSTITUTE(VLOOKUP(B14,VN_Emails!B:H,2,0),"@mapactive.vn","") -> ni.ksormahhko | H14: Office | I14: =J14&" "&K14&" "&L14 -> Laptop Dell Latitude 3520 | J14: Laptop | K14: Dell | L14: Latitude 3520 | M14: BKY5FX3 | N14: 8 | O14: 256 | P14: SSD | Q14: 11TH Gen Intel ® Core™ i5-1135G7 @2.40Ghz | X14: MMA-LAP-0014 | Y14: DONE | Z14: DONE | AA14: DONE | AB14: DONE
A15: =A14+1 -> 14 | B15: 22VN00000015 | C15: In Use | D15: =VLOOKUP(B15,VN_Emails!B:H,4,0) -> Huynh Tuan Nhan | E15: =VLOOKUP(B15,VN_Emails!B:H,7,0) -> SCM Manager | F15: AMMAVNLOC000015 | G15: =SUBSTITUTE(VLOOKUP(B15,VN_Emails!B:H,2,0),"@mapactive.vn","") -> nhan.huynhtuan | H15: Office | I15: =J15&" "&K15&" "&L15 -> Laptop Dell Latitude 5430 | J15: Laptop | K15: Dell | L15: Latitude 5430 | M15: 13D4SQ3 | N15: 16 | O15: 512 | P15: SSD | Q15: 2500 MHz 12th Gen Intel Core i5-1235U | X15: MMA-LAP-0015 | Y15: DONE | Z15: DONE | AA15: DONE | AB15: DONE
A16: =A15+1 -> 15 | B16: 22VN00000016 | C16: Available | D16: =VLOOKUP(B16,VN_Emails!B:H,4,0) -> #N/A | E16: =VLOOKUP(B16,VN_Emails!B:H,7,0) -> #N/A | F16: AMMAVNLOC000016 | G16: =SUBSTITUTE(VLOOKUP(B16,VN_Emails!B:H,2,0),"@mapactive.vn","") -> #N/A | H16: Office | I16: =J16&" "&K16&" "&L16 -> Laptop Dell Latitude 3520 | J16: Laptop | K16: Dell | L16: Latitude 3520 | M16: 99C2LG3 | N16: 12 | O16: 512 | P16: SSD | Q16: 2200 MHz 11th Gen Intel Core i3-1115G4 @ 3.00GHz | T16: Nâng 4gb Ram và 256GB SSD | X16: MMA-LAP-0016 | Y16: DONE | Z16: DONE | AA16: DONE | AB16: DONE
A17: =A16+1 -> 16 | B17: 22VN00000017 | C17: Available | D17: =VLOOKUP(B17,VN_Emails!B:H,4,0) -> #N/A | E17: =VLOOKUP(B17,VN_Emails!B:H,7,0) -> #N/A | F17: AMMAVNWHC000017 | G17: =SUBSTITUTE(VLOOKUP(B17,VN_Emails!B:H,2,0),"@mapactive.vn","") -> #N/A | H17: Office | I17: =J17&" "&K17&" "&L17 -> Laptop Dell Latitude 3520 | J17: Laptop | K17: Dell | L17: Latitude 3520 | M17: JP8VKG3 | N17: 16 | O17: 256 | P17: SSD | Q17: 2200 MHz 11th Gen Intel Core i3-1115G4 @ 3.00GHz | X17: MMA-LAP-0017 | Y17: DONE | Z17: DONE | AA17: DONE | AB17: DONE
A18: =A17+1 -> 17 | B18: 22VN00000018 | C18: In Use | D18: =VLOOKUP(B18,VN_Emails!B:H,4,0) -> Dang Thanh Nam | E18: =VLOOKUP(B18,VN_Emails!B:H,7,0) -> Warehouse and Distribution Supervisor | F18: AMMAVNWHC000018 | G18: =SUBSTITUTE(VLOOKUP(B18,VN_Emails!B:H,2,0),"@mapactive.vn","") -> nam.dangthanh | H18: Office | I18: =J18&" "&K18&" "&L18 -> Laptop Dell Latitude 3520 | J18: Laptop | K18: Dell | L18: Latitude 3520 | M18: JR9VKG3 | N18: 8 | O18: 256 | P18: SSD | Q18: 2200 MHz 11th Gen Intel Core i3-1115G4 @ 3.00GHz | X18: MMA-LAP-0018 | Y18: DONE | Z18: DONE | AA18: DONE | AB18: DONE
A19: =A18+1 -> 18 | B19: 22VN00000019 | C19: Available | E19: =VLOOKUP(B19,VN_Emails!B:H,7,0) -> #N/A | F19: AMMAVNLOC000019 | G19: =SUBSTITUTE(VLOOKUP(B19,VN_Emails!B:H,2,0),"@mapactive.vn","") -> #N/A | H19: Office | I19: =J19&" "&K19&" "&L19 -> Laptop Dell Latitude 3520 | J19: Laptop | K19: Dell | L19: Latitude 3520 | M19: FQ8VKG3 | N19: 8 | O19: 256 | P19: SSD | Q19: 2200 MHz 11th Gen Intel Core i3-1115G4 @ 3.00GHz | X19: MMA-LAP-0019 | Y19: DONE | Z19: DONE | AA19: DONE | AB19: DONE
A20: =A19+1 -> 19 | B20: 22VN00000020 | C20: In Use | D20: Quan Thanh Them | E20: =VLOOKUP(B20,VN_Emails!B:H,7,0) -> COE Manager | F20: AMMAVNCEC000020 | G20: =SUBSTITUTE(VLOOKUP(B20,VN_Emails!B:H,2,0),"@mapactive.vn","") -> them.quanthanh | H20: Office | I20: =J20&" "&K20&" "&L20 -> Laptop Dell Latitude 5430 | J20: Laptop | K20: Dell | L20: Latitude 5430 | M20: 5BD4SQ3 | N20: 16 | O20: 512 | P20: SSD | Q20: 2500 MHz 12th Gen Intel Core i5-1235U | X20: MMA-LAP-0020 | Y20: DONE | Z20: DONE | AA20: DONE | AB20: DONE
A21: =A20+1 -> 20 | B21: 22VN00000021 | C21: In Use | D21: =VLOOKUP(B21,VN_Emails!B:H,4,0) -> Nguyen Ngoc Xuan Duyen | E21: =VLOOKUP(B21,VN_Emails!B:H,7,0) -> COE Officer | F21: AMMAVNCEC000021 | G21: =SUBSTITUTE(VLOOKUP(B21,VN_Emails!B:H,2,0),"@mapactive.vn","") -> duyen.nguyenngocxuan | H21: Office | I21: =J21&" "&K21&" "&L21 -> Laptop Dell Latitude 3520 | J21: Laptop | K21: Dell | L21: Latitude 3520 | M21: BTN0BG3 | N21: 8 | O21: 256 | P21: SSD | Q21: 2200 MHz 11th Gen Intel Core i3-1115G4 @ 3.00GHz | X21: MMA-LAP-0021 | Y21: DONE | Z21: DONE | AA21: DONE | AB21: DONE
A22: =A21+1 -> 21 | B22: 22VN00000022 | C22: In Use | D22: =VLOOKUP(B22,VN_Emails!B:H,4,0) -> Nguyen Quyet Thang | E22: =VLOOKUP(B22,VN_Emails!B:H,7,0) -> COE Officer | F22: AMMAVNCEC000022 | G22: =SUBSTITUTE(VLOOKUP(B22,VN_Emails!B:H,2,0),"@mapactive.vn","") -> thang.nguyenquyet | H22: Office | I22: =J22&" "&K22&" "&L22 -> Laptop Dell Latitude 3520 | J22: Laptop | K22: Dell | L22: Latitude 3520 | M22: DP8VKG3 | N22: 8 | O22: 256 | P22: SSD | Q22: 2200 MHz 11th Gen Intel Core i3-1115G4 @ 3.00GHz | V22: LE MINH KHANG OLD LAPTOP (COE Officer) resigned 29-01-2024 - 25/03/2024 handover for Tạ Quỳnh Trang -16/07/2024 handover for Trần Hồ Duy Tân | X22: MMA-LAP-0022 | Y22: DONE | Z22: DONE | AA22: DONE | AB22: DONE
A23: =A22+1 -> 22 | B23: 22VN00000023 | C23: In Use | D23: =VLOOKUP(B23,VN_Emails!B:H,4,0) -> Nguyen Bao Du | E23: =VLOOKUP(B23,VN_Emails!B:H,7,0) -> HR Internship | F23: AMMAVNCEC000023 | G23: =SUBSTITUTE(VLOOKUP(B23,VN_Emails!B:H,2,0),"@mapactive.vn","") -> du.nguyenbao | H23: Office | I23: =J23&" "&K23&" "&L23 -> Laptop Dell Latitude 3520 | J23: Laptop | K23: Dell | L23: Latitude 3520 | M23: 6S4JGL3 | N23: 8 | O23: 256 | P23: SSD | Q23: 1400 MHz 11th Gen Intel Core i5-1135G7 @ 2.40GHz | V23: - Tran Dang Anh Khoa (COE Officer) resigned - Cấp tạm cho DƯƠNG QUANG MINH TUẤN THAY cho HỒ HẢI ĐĂNG AM IT ĐÃ THU HỒI 30-01-24 | W23: DISABLE | X23: MMA-LAP-0023 | Y23: DONE | Z23: DONE | AA23: DONE | AB23: DONE | AC23: DONE
A24: =A23+1 -> 23 | B24: 22VN00000024 | C24: Available | D24: =VLOOKUP(B24,VN_Emails!B:H,4,0) -> #N/A | E24: =VLOOKUP(B24,VN_Emails!B:H,7,0) -> #N/A | F24: AMMAVNICC000024 | G24: =SUBSTITUTE(VLOOKUP(B24,VN_Emails!B:H,2,0),"@mapactive.vn","") -> #N/A | H24: Office | I24: =J24&" "&K24&" "&L24 -> Laptop Dell Latitude 3520 | J24: Laptop | K24: Dell | L24: Latitude 3520 | M24: 4R9VKG3 | N24: 8 | O24: 256 | P24: SSD | Q24: 2200 MHz 11th Gen Intel Core i3-1115G4 @ 3.00GHz | X24: MMA-LAP-0024 | Y24: DONE | Z24: DONE | AA24: DONE | AB24: DONE
A25: =A24+1 -> 24 | B25: 22VN00000025 | C25: In Use | D25: =VLOOKUP(B25,VN_Emails!B:H,4,0) -> Luong Huu Quan | E25: =VLOOKUP(B25,VN_Emails!B:H,7,0) -> IT Infrastructure & Operations Supervisor | F25: AMMAVNITC000025 | G25: =SUBSTITUTE(VLOOKUP(B25,VN_Emails!B:H,2,0),"@mapactive.vn","") -> quan.luonghuu | H25: Office | I25: =J25&" "&K25&" "&L25 -> Laptop Dell Latitude 5430 | J25: Laptop | K25: Dell | L25: Latitude 5430 | M25: FGF3SQ3 | N25: 16 | O25: 512 | P25: SSD | Q25: 2500 MHz 12th Gen Intel Core i5-1235U | X25: MMA-LAP-0025 | Y25: DONE | Z25: DONE | AA25: DONE | AB25: DONE
A26: =A25+1 -> 25 | B26: 22VN00000026 | C26: Available | D26: IT BACKUP | E26: =VLOOKUP(B26,VN_Emails!B:H,7,0) -> #N/A | F26: AMMAVNITC000026 | G26: =SUBSTITUTE(VLOOKUP(B26,VN_Emails!B:H,2,0),"@mapactive.vn","") -> #N/A | H26: Office | I26: =J26&" "&K26&" "&L26 -> Laptop HP ProBook 440 G4 | J26: Laptop | K26: HP | L26: ProBook 440 G4 | M26: 5CD73626Y5 | N26: 16 | O26: 256 | P26: SSD | Q26: 2700 MHz Core i5-7200U | T26: anh.nguyenphamduy resigned 20/05/2024 | V26: -Dat.tranquoc (IT Officer) resigned 11/3/2024 | X26: MMA-LAP-0026 | Y26: DONE | Z26: DONE | AA26: DONE | AB26: DONE | AC26: DONE
A27: =A26+1 -> 26 | B27: 22VN00000027 | C27: In Use | D27: =VLOOKUP(B27,VN_Emails!B:H,4,0) -> Huynh My Danh | E27: =VLOOKUP(B27,VN_Emails!B:H,7,0) -> FP&A Supervisor | F27: AMMAVNMRC000027 | G27: =SUBSTITUTE(VLOOKUP(B27,VN_Emails!B:H,2,0),"@mapactive.vn","") -> danh.huynhmy | H27: Office | I27: =J27&" "&K27&" "&L27 -> Laptop Dell Latitude 5420 | J27: Laptop | K27: Dell | L27: Latitude 5420 | M27: HRQCZH3 | N27: 8 | O27: 512 | P27: SSD | Q27: 1400 MHz 11th Gen Intel Core i5-1135G7 @ 2.40GHz | X27: MMA-LAP-0027 | Y27: DONE | Z27: DONE | AA27: DONE | AB27: DONE
A28: =A27+1 -> 27 | B28: 22VN00000028 | C28: In Use | D28: =VLOOKUP(B28,VN_Emails!B:H,4,0) -> Nghiem Thi Hong Van | E28: =VLOOKUP(B28,VN_Emails!B:H,7,0) -> Senior Merchandise | F28: AMMAVNMDCC000028 | G28: =SUBSTITUTE(VLOOKUP(B28,VN_Emails!B:H,2,0),"@mapactive.vn","") -> van.nghiemthihong | H28: Office | I28: =J28&" "&K28&" "&L28 -> Laptop Dell Latitude 3520 | J28: Laptop | K28: Dell | L28: Latitude 3520 | M28: GN8VKG3 | N28: 12 | O28: 256 | P28: SSD | Q28: 2200 MHz 11th Gen Intel Core i3-1115G4 @ 3.00GHz | T28: BÀN GIAO CHO Nghiêm Thị Hồng Vân – Senior Merchandise – Brand Department – On board 15/10/2023 (nâng 4gb Ram) | V28: MÁY CŨ LÊ TRẦN THIÊN MINH | X28: MMA-LAP-0028 | Y28: DONE | Z28: DONE | AA28: DONE | AB28: DONE
A29: =A28+1 -> 28 | B29: 22VN00000029 | C29: In Use | D29: VA04-ADMIN | E29: =VLOOKUP(B29,VN_Emails!B:H,7,0) -> #N/A | F29: VA04-ADMIN | G29: =SUBSTITUTE(VLOOKUP(B29,VN_Emails!B:H,2,0),"@mapactive.vn","") -> #N/A | H29: Office | I29: =J29&" "&K29&" "&L29 -> Laptop Dell Latitude 3520 | J29: Laptop | K29: Dell | L29: Latitude 3520 | M29: 1P8VKG3 | N29: 8 | O29: 256 | P29: SSD | Q29: 2200 MHz 11th Gen Intel Core i3-1115G4 @ 3.00GHz | T29: Máy cũ Minh (sracecrow) | V29: Pham Thi Bao Tram (MKT) handover Feb-29-2024 Old hostname: AMMAVNMRC000029 | X29: MMA-LAP-0029 | Y29: DONE | Z29: DONE | AA29: DONE | AB29: DONE
A30: =A29+1 -> 29 | B30: 22VN00000030 | C30: Available | E30: =VLOOKUP(B30,VN_Emails!B:H,7,0) -> #N/A | F30: AMMAVNMRC000030 | G30: =SUBSTITUTE(VLOOKUP(B30,VN_Emails!B:H,2,0),"@mapactive.vn","") -> #N/A | H30: Office | I30: =J30&" "&K30&" "&L30 -> Laptop Lenovo Thinkpad X280 | J30: Laptop | K30: Lenovo | L30: Thinkpad X280 | M30: PC133K78 | N30: 8 | O30: 256 | P30: SSD | Q30: 1800 MHz Core i5-8250U | T30: - Replaced keyboard on 20-Aug-2023 cấp cho :Nguyen Thao My 27/11/2023 (replace Phan Thi Thuy Tien) | V30: - Phan Thị Thủy Tiên đã thôi việc ngày 06/10/23 - Huỳnh Thị Bích Ngân – thôi việc ngày 13/10/2023 | X30: MMA-LAP-0030 | Y30: DONE | Z30: DONE | AA30: DONE | AB30: DONE | AC30: DONE
A31: =A30+1 -> 30 | B31: 22VN00000031 | C31: Available | D31: =VLOOKUP(B31,VN_Emails!B:H,4,0) -> #N/A | E31: =VLOOKUP(B31,VN_Emails!B:H,7,0) -> #N/A | F31: AMMAVNMDC000031 | G31: =SUBSTITUTE(VLOOKUP(B31,VN_Emails!B:H,2,0),"@mapactive.vn","") -> #N/A | H31: Office | I31: =J31&" "&K31&" "&L31 -> Laptop Dell Latitude 5420 | J31: Laptop | K31: Dell | L31: Latitude 5420 | M31: 4DBCZH3 | N31: 8 | O31: 512 | P31: SSD\ | Q31: 1400 MHz 11th Gen Intel Core i5-1135G7 @ 2.40GHz | X31: MMA-LAP-0031 | Y31: DONE | Z31: DONE | AA31: DONE | AB31: DONE
A32: =A31+1 -> 31 | B32: 22VN00000032 | C32: In Use | D32: =VLOOKUP(B32,VN_Emails!B:H,4,0) -> Vu Xuan Uyen | E32: =VLOOKUP(B32,VN_Emails!B:H,7,0) -> Marketing officer | F32: AMMAVNLEC000032 | G32: =SUBSTITUTE(VLOOKUP(B32,VN_Emails!B:H,2,0),"@mapactive.vn","") -> uyen.vuxuan | H32: Office | I32: =J32&" "&K32&" "&L32 -> Laptop Dell Latitude 3420 | J32: Laptop | K32: Dell | L32: Latitude 3420 | M32: 6GV7R93 | N32: 8 | O32: 640 | P32: HDD (512 GB) SSD (128 GB) | Q32: 1400 MHz 11th Gen Intel Core i5-1135G7 @ 2.40GHz | T32: Quỳnh MD Bàn giao trả máy ngày 24/08/2023 > Chuyển sang cho Le Thi Kim Hồng (Legal) sử dụng ngày 11/09/2023 | W32: use USB token | X32: MMA-LAP-0032 | Y32: DONE | Z32: DONE | AA32: DONE | AB32: DONE
A33: =A32+1 -> 32 | B33: 22VN00000033 | C33: Available | D33: =VLOOKUP(B33,VN_Emails!B:H,4,0) -> #N/A | E33: =VLOOKUP(B33,VN_Emails!B:H,7,0) -> #N/A | F33: AMMAVNMDC000033 | G33: =SUBSTITUTE(VLOOKUP(B33,VN_Emails!B:H,2,0),"@mapactive.vn","") -> #N/A | H33: Office | I33: =J33&" "&K33&" "&L33 -> Laptop Dell Latitude 3520 | J33: Laptop | K33: Dell | L33: Latitude 3520 | M33: 9P8VKG3 | N33: 8 | O33: 256 | P33: SSD | Q33: 2200 MHz 11th Gen Intel Core i3-1115G4 @ 3.00GHz | X33: MMA-LAP-0033 | Y33: DONE | Z33: DONE | AA33: DONE | AB33: DONE
A34: =A33+1 -> 33 | B34: 22VN00000034 | C34: In Use | D34: =VLOOKUP(B34,VN_Emails!B:H,4,0) -> Tran A giang | E34: =VLOOKUP(B34,VN_Emails!B:H,7,0) -> Intern | F34: AMMAVNMDC000034 | G34: =SUBSTITUTE(VLOOKUP(B34,VN_Emails!B:H,2,0),"@mapactive.vn","") -> giang.trana | H34: Office | I34: =J34&" "&K34&" "&L34 -> Laptop Dell Latitude 3520 | J34: Laptop | K34: Dell | L34: Latitude 3520 | M34: DGBJGL3 | N34: 8 | O34: 256 | P34: SSD | Q34: 1400 MHz 11th Gen Intel Core i5-1135G7 @ 2.40GHz | X34: MMA-LAP-0034 | Y34: DONE | Z34: DONE | AA34: DONE | AB34: DONE
A35: =A34+1 -> 34 | B35: 22VN00000035 | C35: In Use | D35: =VLOOKUP(B35,VN_Emails!B:H,4,0) -> Dang Thi Thanh Tam | E35: =VLOOKUP(B35,VN_Emails!B:H,7,0) -> Brand Manager (NB, Crocs) | F35: AMMAVNMDC000035 | G35: =SUBSTITUTE(VLOOKUP(B35,VN_Emails!B:H,2,0),"@mapactive.vn","") -> tam.dangthithanh | H35: Office | I35: =J35&" "&K35&" "&L35 -> Laptop Dell Latitude 5420 | J35: Laptop | K35: Dell | L35: Latitude 5420 | M35: 4CBCZH3 | N35: 12 | O35: 512 | P35: SSD | Q35: 1400 MHz 11th Gen Intel Core i5-1135G7 @ 2.40GHz | X35: MMA-LAP-0035 | Y35: DONE | Z35: DONE | AA35: DONE | AB35: DONE
A36: =A35+1 -> 35 | B36: 22VN00000036 | C36: Reserved | D36: KN10 bán cho Maison | E36: =VLOOKUP(B36,VN_Emails!B:H,7,0) -> #N/A | F36: AMMAVNMDC000036 | G36: =SUBSTITUTE(VLOOKUP(B36,VN_Emails!B:H,2,0),"@mapactive.vn","") -> #N/A | H36: Office | I36: =J36&" "&K36&" "&L36 -> Laptop Lenovo Ideapad 5-15ITL05(82FG00M5VN) | J36: Laptop | K36: Lenovo | L36: Ideapad 5-15ITL05(82FG00M5VN) | M36: PF2Q30RQ | N36: 8 | O36: 512 | P36: SSD | Q36: 2400 MHz 11th Gen Intel Core i5-1135G7 @ 2.40GHz | T36: - Old laptop of Pham My Tu - Cần cài lại Windows | V36: - Old laptop of Pham My Tu | X36: MMA-LAP-0036 | Y36: DONE | Z36: DONE | AA36: DONE | AB36: DONE
A37: =A36+1 -> 36 | B37: 22VN00000037 | C37: In Use | D37: =VLOOKUP(B37,VN_Emails!B:H,4,0) -> Nguyen Phuoc Thanh | E37: =VLOOKUP(B37,VN_Emails!B:H,7,0) -> Merchandiser | F37: AMMAVNMDC000037 | G37: =SUBSTITUTE(VLOOKUP(B37,VN_Emails!B:H,2,0),"@mapactive.vn","") -> thanh.nguyenphuoc | H37: Office | I37: =J37&" "&K37&" "&L37 -> Laptop Dell Latitude 3520 | J37: Laptop | K37: Dell | L37: Latitude 3520 | M37: 6Q7JGL3 | N37: 12 | O37: 512 | P37: SSD | Q37: 1400 MHz 11th Gen Intel Core i5-1135G7 @ 2.40GHz | X37: MMA-LAP-0037 | Y37: DONE | Z37: DONE | AA37: DONE | AB37: DONE
A38: =A37+1 -> 37 | B38: 22VN00000038 | C38: In Use | D38: =VLOOKUP(B38,VN_Emails!B:H,4,0) -> Ngo Thi Bich Tram | E38: =VLOOKUP(B38,VN_Emails!B:H,7,0) -> Shipping Officer | F38: AMMAVNMDC000038 | G38: =SUBSTITUTE(VLOOKUP(B38,VN_Emails!B:H,2,0),"@mapactive.vn","") -> tram.ngothibich | H38: Office | I38: =J38&" "&K38&" "&L38 -> Laptop Dell Latitude 5430 | J38: Laptop | K38: Dell | L38: Latitude 5430 | M38: 4TS3SQ3 | N38: 16 | O38: 512 | P38: SSD | Q38: 2500 MHz 12th Gen Intel Core i5-1235U | V38: Máy của TRƯƠNG HỒNG HƯƠNG BÀN GIAO (HIếu IT giữ) | X38: MMA-LAP-0038 | Y38: DONE | Z38: DONE | AA38: DONE | AB38: DONE
A39: ost | B39: 22VN00000039 | C39: In Use | D39: =VLOOKUP(B39,VN_Emails!B:H,4,0) -> Le Ngoc Bich Tram | E39: =VLOOKUP(B39,VN_Emails!B:H,7,0) -> Marketing Supervisor (Foot Locker) | F39: AMMAVNIT000039 | G39: =SUBSTITUTE(VLOOKUP(B39,VN_Emails!B:H,2,0),"@mapactive.vn","") -> tram.lengocbich | H39: Office | I39: =J39&" "&K39&" "&L39 -> Laptop Dell Latitude 3520 | J39: Laptop | K39: Dell | L39: Latitude 3520 | M39: HGBJGL3 | N39: 20 | O39: 256+512 | P39: SSD | Q39: 1400 MHz 11th Gen Intel Core i5-1135G7 @ 2.40GHz | V39: linh.thainhat resigned 24/04/2024 | X39: MMA-LAP-0039 | Y39: DONE | Z39: DONE | AA39: DONE | AB39: DONE
A40: =Asset_Store!A435+1 -> 413 | B40: 22VN00000041 | C40: In Use | D40: =VLOOKUP(B40,VN_Emails!B:H,4,0) -> Nguyen Thi Tuyet Nhung | E40: =VLOOKUP(B40,VN_Emails!B:H,7,0) -> Senior Merchandise | F40: AMMAVNBPC000041 | G40: =SUBSTITUTE(VLOOKUP(B40,VN_Emails!B:H,2,0),"@mapactive.vn","") -> nhung.nguyenthituyet | H40: Office | I40: =J40&" "&K40&" "&L40 -> Laptop Dell Latitude 5430 | J40: Laptop | K40: Dell | L40: Latitude 5430 | M40: GB23SQ3 | N40: 16 | O40: 512 | P40: SSD | Q40: 2500 MHz 12th Gen Intel Core i5-1235U | T40: User giang.nguyenthiquynh bàn giao ngày 18/08/2023 | V40: IT nhận máy bh ssd lỗi ngày 06/02/24(cmc)> BH SAU TẾT đã bh xong bàn giao user ngày 29/02/24 | W40: DISABLE | X40: MMA-LAP-0041 | Y40: DONE | Z40: DONE | AA40: DONE | AB40: DONE | AC40: DONE
...

Sheet VN_Emails
A1: No. | B1: Assigned Asset | C1: Email Address | D1: Full Name | E1: Display Name | F1: English Name | G1: Department | H1: JOB TITLE | I1: O365 license | J1: Country | K1: Type | L1: Onboarding Date | M1: Request email | N1: Purchasing Request | O1: Laptop model | P1: Laptop delivery | Q1: Handover to user | R1: Notes | S1: MAP Level
A2: 1 | B2: 22VN00000086 | C2: uyen.nguyenhaphuong@mapactive.vn | D2: Nguyễn Hà Phượng Uyên | E2: Nguyen Ha Phuong Uyen | F2: Dory | G2: BOD (Finance) | H2: General Manager & Finance Controller | I2: E3 | J2: VN | K2: Office | S2: Senior General Manager
A3: 2 | B3: 22VN00000001 | C3: phung.tietnha@mapactive.vn | D3: Tiết Nhã Phụng | E3: Tiet Nha Phung | H3: Brand Manager (Converse) | I3: E3 | J3: VN | K3: Office | S3: Senior Manager
A4: 3 | B4: 22VN00000035 | C4: tam.dangthithanh@mapactive.vn | D4: Đặng Thị Thanh Tâm | E4: Dang Thi Thanh Tam | F4: Tansy | H4: Brand Manager (NB, Crocs) | I4: E3 | J4: VN | K4: Office | S4: Senior Manager
A5: 4 | B5: 22VN00000097 | C5: van.luugiangcam@mapactive.vn | D5: Lưu Giang Cẩm Vân | E5: Luu Giang Cam Van | F5: Vicky | H5: HR & Admin Manager | I5: E3 | J5: VN | K5: Office | S5: Manager
A6: 5 | B6: 22VN00000020 | C6: them.quanthanh@mapactive.vn | D6: Quan Thanh Thềm | E6: Quan Thanh Them | H6: COE Manager | I6: E3 | J6: VN | K6: Office | S6: Manager
A7: 6 | B7: 22VN00000099 | C7: nghia.thoihuu@mapactive.vn | D7: Thới Hũu Nghĩa | E7: Thoi Huu Nghia | H7: Senior Project Manager | I7: E3 | J7: VN | K7: Office | S7: Senior Manager
A8: 7 | B8: 22VN00000103 | C8: tuyen.vothuyminh@mapactive.vn | D8: Võ Thụy Minh Tuyền | E8: Vo Thuy Minh Tuyen | H8: Senior Merchandise | I8: E3 | J8: VN | K8: Office | S8: Associate Manager
A9: 8 | B9: 22VN00000101 | C9: tu.phammy@mapactive.vn | D9: Phạm Mỹ Tú | E9: Pham My Tu | H9: Senior Merchandise | I9: E3 | J9: VN | K9: Office | S9: Associate Manager
A10: 9 | B10: 22VN00000037 | C10: thanh.nguyenphuoc@mapactive.vn | D10: Nguyễn Phước Thạnh | E10: Nguyen Phuoc Thanh | H10: Merchandiser | I10: E3 | J10: VN | K10: Office | S10: Senior Executive
A11: 10 | B11: 22VN00000009 | C11: linh.lecam@mapactive.vn | D11: Lê Cẩm Linh | E11: Le Cam Linh | H11: Shipping Supervisor | I11: E3 | J11: VN | K11: Office | S11: Senior Executive
A12: 11 | B12: 22VN00000038 | C12: tram.ngothibich@mapactive.vn | D12: Ngô Thị Bích Trâm | E12: Ngo Thi Bich Tram | H12: Shipping Officer | I12: E3 | J12: VN | K12: Office | S12: Senior Associate
A13: 12 | B13: 22VN00000076 | C13: tuyet.lethianh@mapactive.vn | D13: Lê Thị Ánh Tuyết | E13: Le Thi Anh Tuyet | H13: Tax & Accounting Assistant Manager | I13: E3 | J13: VN | K13: Office | S13: Senior Associate
A14: 13 | B14: 22VN00000094 | C14: tuan.ngoanh@mapactive.vn | D14: Ngô Anh Tuấn | E14: Ngo Anh Tuan | H14: Senior Wholesaler | I14: E3 | J14: VN | K14: Office | S14: Executive
A15: 14 | B15: 22VN00000102 | C15: thang.nguyennam@mapactive.vn | D15: Nguyễn Nam Thắng | E15: Nguyen Nam Thang | H15: Senior Wholesaler | I15: E3 | J15: VN | K15: Office | S15: Executive
A16: 15 | B16: 22VN00000018 | C16: nam.dangthanh@mapactive.vn | D16: Đặng Thành Nam | E16: Dang Thanh Nam | H16: Warehouse and Distribution Supervisor | I16: E3 | J16: VN | K16: Office | S16: Senior Executive
A17: 16 | B17: 22VN00000098 | C17: quynh.mainguyendiem@mapactive.vn | D17: Mai Nguyễn Diễm Quỳnh | E17: Mai Nguyen Diem Quynh | H17: Payable Accountant | I17: E3 | J17: VN | K17: Office | S17: Senior Associate
... A24: 24 | B24: 22VN00000066 | C24: tram.duongthibao@mapactive.vn | D24: Dương Thị Bảo Trâm | E24: Duong Thi Bao Tram | H24: Wholesale Admin | I24: E3 | J24: VN | K24: Office | S24: Associate
A25: 25 | B25: 22VN00000078 | C25: anh.nguyenngoclan@mapactive.vn | D25: Nguyễn Ngọc Lan Anh | E25: Nguyen Ngoc Lan Anh | F25: Sophie | H25: Graphic Designer | I25: E3 | J25: VN | K25: Office | S25: Senior Executive
A26: 26 | B26: 22VN00000044 | C26: trinh.tranngocdoan@mapactive.vn | D26: Trần Ngọc Đoan Trinh | E26: Tran Ngoc Doan Trinh | H26: Senior Merchandise | I26: E3 | J26: VN | K26: Office | S26: Senior Manager
A27: 27 | B27: 22VN00000061 | C27: linh.lengocmy@mapactive.vn | D27: Lê Ngoc Mỹ Linh | E27: Le Ngoc My Linh | H27: Senior Merchandise | I27: E3 | J27: VN | K27: Office | L27: 44958
A28: 28 | B28: 22VN00000013 | C28: nhi.tranthiyen@mapactive.vn | D28: Trần Thị Yến Nhi | E28: Tran Thi Yen Nhi | H28: Payroll & Em. Servieces Executive | I28: E3 | J28: VN | K28: Office | S28: Senior Associate
A29: 29 | B29: 22VN00000014 | C29: ni.ksormahhko@mapactive.vn | D29: Ksormahhko NI | E29: Ni Ksormahhko | H29: Procurement Executive | I29: E3 | J29: VN | K29: Office | S29: Senior Associate
A30: 30 | B30: 22VN00000065 | C30: lan.nguyenphuong@mapactive.vn | D30: Nguyễn Phương Lan | E30: Nguyen Phuong Lan | G30: Legal | H30: Legal Manager | I30: E3 | J30: VN | K30: Office | L30: 44991 | M30: Done | N30: Done | O30: 5430 | P30: Done | Q30: Done
A31: 31 | B31: 22VN00000106 | C31: syed.umairhassan@mapactive.vn | D31: Syed Umair Hassan | E31: Syed Umair Hassan | G31: BOD (Merchandise) | H31: GM Merchandise | I31: E3 | J31: VN | K31: Office | L31: 45005 | M31: Done | Q31: Done | R31: Using the HP Laptop of Birkenstock Diamond Plaza
A32: 32 | B32: 22VN00000025 | C32: quan.luonghuu@mapactive.vn | D32: Lương Hữu Quân | E32: Luong Huu Quan | G32: IT | H32: IT Infrastructure & Operations Supervisor | I32: E3 | J32: VN | K32: Office | L32: 45012 | M32: Done | N32: Done | O32: 3520 | P32: Done | Q32: Done
A33: 33 | B33: 22VN00000015 | C33: nhan.huynhtuan@mapactive.vn | D33: Huỳnh Tuấn Nhân | E33: Huynh Tuan Nhan | G33: SCM | H33: SCM Manager | I33: E3 | J33: VN | K33: Office | L33: 45019 | M33: Done | N33: No need | O33: No need | P33: No need | R33: Re-use the laptop of ngoc.voleminh
A34: 34 | B34: 22VN00000004 | C34: mong.nguyenthithuy@mapactive.vn | D34: Nguyễn Thị Thúy Mộng | E34: Nguyen Thi Thuy Mong | G34: Merchandise | H34: Senior Brand Marketing Manager | I34: E3 | J34: VN | K34: Office | L34: 45026 | M34: Done | N34: Done | O34: 5430 | R34: Foot Locker
A35: 35 | B35: 22VN00000070 | C35: qui.nguyenthi@mapactive.vn | D35: Nguyễn Thị Quí | E35: Nguyen Thi Qui | G35: Accounting | H35: General Accountant UFO | I35: E3 | J35: VN | K35: Office | L35: 45054 | M35: Done | N35: No need | O35: No need | R35: Re-use Nguyễn Trí Độ' Laptop
A36: 36 | B36: 22VN00000072 | C36: le.daothihong@mapactive.vn | D36: Đào Thị Hồng Lê | E36: Dao Thi Hong Le | G36: Training | H36: Training Assistant Manager | I36: E3 | J36: VN | K36: Office | L36: 45069 | M36: Done | N36: done | O36: 5430
A37: 37 | B37: 22VN00000042 | C37: dien.tranduy@mapactive.vn | D37: Trần Duy Điền | E37: Tran Duy Dien | G37: COE Department | H37: Inventory Control | I37: E3 | J37: VN | K37: Office | L37: 45078 | M37: Done | N37: No need | O37: 3520
A38: 38 | B38: 22VN00000080 | C38: thu.nguyenthanhanh@mapactive.vn | D38: Nguyễn Thanh Anh Thư | E38: Nguyen Thanh Anh Thu | G38: Marketing Department | H38: Visual Merchandise Manager | I38: E3 | J38: VN | K38: Office | L38: 45083 | M38: Done | N38: Done | O38: 5430
A39: 39 | B39: 22VN00000071 | C39: Huy.daoduc@mapactive.vn | D39: Đào Đức Huy | E39: Dao Duc Huy | G39: Operations Department | H39: Area Manager (South) | I39: E3 | J39: VN | K39: Office | L39: 45110 | M39: Done | N39: Done | O39: 5430
A40: 40 | B40: 22VN00000023 | C40: du.nguyenbao@mapactive.vn | D40: Nguyễn Bảo Du | E40: Nguyen Bao Du | G40: HR Department | H40: HR Internship | I40: None | J40: VN | K40: Office | L40: 45139 | M40: No need | N40: Done | O40: Mini PC
A41: 41 | B41: 22VN00000079 | C41: duyen.lethanh@mapactive.vn | D41: Lê Thanh Duyên | E41: Le Thanh Duyen | G41: Marketing Department | H41: Graphic Designer (Foot Locker) | I41: E3 | J41: VN | K41: Office | L41: 45146 | M41: Done | N41: No need | R41: Re-use Vũ Xuân Sơn
A42: 42 | B42: 22VN00000104 | C42: ngoc.nguyenduyen@mapactive.vn | D42: Nguyễn Duyên Ngọc | E42: Nguyen Duyen Ngoc | G42: Business Development | H42: Business Development Manager | I42: E3 | J42: VN | K42: Office | L42: 45174 | M42: Done | N42: No need | O42: 5430 | P42: Done | Q42: Done | R42: Thay anh Hiếu BD (hieu.trantrung)last day ngày 31/08 dùng lại laptop | S42: Business Development Manager
A43: 43 | B43: 22VN00000028 | C43: van.nghiemthihong@mapactive.vn | D43: Nghiêm Thị Hồng Vân | E43: Nghiem Thi Hong Van | G43: Brand Department | H43: Senior Merchandise | I43: E3 | J43: VN | K43: Office | L43: 45214
A44: 44 | B44: 22VN00000052 | C44: xuan.vothihoanganh@mapactive.vn | D44: Võ Thị Hoàng Ánh Xuân | E44: Vo Thi Hoang Anh Xuan | G44: Operations | H44: Operations Executive | I44: E3 | J44: VN | K44: Office | L44: 45218 | M44: None | N44: No need | O44: 7490 | R44: Dùng lại máy ĐẶNG QUỐC TRÍ (OP)
A45: 45 | B45: 22VN00000039 | C45: tram.lengocbich@mapactive.vn | D45: Lê Ngọc BÍch Trâm | E45: Le Ngoc Bich Tram | G45: Marketing Department (Foot Locker) | H45: Marketing Supervisor (Foot Locker) | I45: E3 | J45: VN | K45: Office | L45: 45219 | M45: Done | N45: No need | O45: x280 | Q45: Done | R45: Replace Phạm Thị Mỹ Dung
A46: 46 | B46: 22VN00000051 | C46: mai.nguyenthihuynh@mapactive.vn | D46: Nguyễn Thị Huỳnh Mai | E46: Nguyen Thi Huynh Mai | F46: Maya | H46: Finance, Tax & Accounting Manager | I46: E3 | J46: VN | K46: Office | Q46: Done | R46: laptop cũ của Huỳnh Ngọc Sơn (team Project)
...

Sheet Office_Resigned
A1: Disable Email | B1: No. | C1: Assigned Asset | D1: Email Address | E1: Full Name | F1: Display Name | G1: English Name | H1: Department | I1: JOB TITLE | J1: O365 license | K1: Country | L1: Type | M1: Onboarding Date (dd/mm/yy) | N1: Request email | O1: Purchasing Request | P1: Laptop model | Q1: Laptop delivery | R1: Handover to user | S1: Notes | T1: MAP Level
A3: Request ITSD, IT Server Operation on 23 Feb 2023 (Ticket : WO0000000107284) | B3: 1 | D3: alun.hughes@mapactive.vn | F3: Alun Hughes | J3: Exchange Online Kiosk
A4: Need to check with anh Nhân Log | B4: =B3+1 -> 2 | D4: loan.lethikim@mapactive.vn | I4: Shipping Executive | J4: E3 | M4: 15/02/2023 | N4: Done | P4: 3520 | Q4: Done | R4: Done | S4: đã nghỉ việc
A5: Done | B5: =B4+1 -> 3 | D5: ngoc.voleminh@mapactive.vn | I5: Logistics Manager | J5: E3 | S5: đã nghỉ việc | T5: Manager
A6: Done | B6: =B5+1 -> 4 | D6: trung.lehominh@mapactive.vn | E6: Lê Hồ Minh Trung | F6: Le Ho Minh Trung | H6: Digital | I6: Digital Commercial Senior Manager | J6: E3 | K6: VN | M6: 03/04/2023 | N6: Done | O6: Done | P6: 5430 | S6: đã nghỉ việc
A7: Done | B7: =B6+1 -> 5 | D7: tram.nguyhuynhmai@mapactive.vn | E7: Ngụy Huỳnh Mai Trâm | F7: Nguy Huynh Mai Tram | H7: Logistic | I7: Logistic Admin | J7: E3 | K7: VN | M7: 14/04/2023 | S7: đã nghỉ việc | T7: Associate
A8: Done | B8: =B7+1 -> 6 | D8: nhung.nguyenhong@mapactive.vn | E8: Nguyễn Hồng Nhung | F8: Nguyen Hong Nhung | H8: Training | I8: Training Assistant Manager | J8: E3 | K8: VN | M8: 14/04/2023 | S8: đã nghỉ việc | T8: Associate Manager
A9: Done | B9: =B8+1 -> 7 | D9: ha.dangthivan@mapactive.vn | E9: Đặng Thị Vân Hà | F9: Dang Thi Van Ha | H9: Merchandise | I9: Merchandise | K9: VN | M9: 14/04/2023 | S9: đã nghỉ việc
A10: Done | B10: =B9+1 -> 8 | D10: hau.lenguyentrung@mapactive.vn | E10: Lê Nguyễn Trung Hậu | F10: Le Nguyen Trung Hau | H10: Merchandise | I10: Visual Merchandise Supervisor | K10: VN | M10: 17/04/2023 | N10: Done | O10: Done | P10: 5430 (swap for Henry) | S10: đã nghỉ việc
A11: Done | B11: =B10+1 -> 9 | D11: do.nguyentri@mapactive.vn | E11: Nguyễn Trí Độ | F11: Nguyen Tri Do | H11: Accounting | I11: General Accounting | J11: E3 | K11: VN | M11: 03/04/2023 | N11: Done | O11: Done | P11: 5430 | S11: đã nghỉ việc
A12: Done | B12: =B11+1 -> 10 | D12: nghia.letrong@mapactive.vn | E12: Lê Trọng Nghĩa | F12: Le Trong Nghia | H12: Training | I12: Training Assistant Manager | K12: VN | M12: 24/04/2023 | N12: Done | O12: Done | P12: Re use Laptop Chị Nhung | Q12: Re use Laptop Chị Nhung | S12: đã nghỉ việc
A13: Done | B13: =B12+1 -> 11 | D13: duong.nguyenthihai@mapactive.vn | I13: Internal Audit & Business Process Assistant Manager | J13: E3 | K13: VN | M13: 01/03/2023 | N13: Done | O13: Done | P13: 5430 | Q13: Done | R13: Done | S13: đã nghỉ việc
A14: Done | B14: =B13+1 -> 12 | D14: thuy.dangtranthu@mapactive.vn | I14: Marketing Executive | J14: E3 | K14: VN | M14: 14/07/2023 | N14: Done | O14: Done | P14: 3520 | S14: Disable email after 09/2023 | T14: Executive
A15: Done | B15: =B14+1 -> 13 | D15: son.vuxuan@mapactive.vn | E15: Vũ Xuân Sơn | F15: Vu Xuan Son | H15: Marketing Department | I15: Graphic Designer (Foot Locker) | K15: vn | M15: 15/06/2023 | N15: Done | O15: Done | S15: đã nghỉ việc
A16: Need to keep until end of Oct-2023 | B16: =B15+1 -> 14 | D16: giang.nguyenthiquynh@map.co.id | I16: Merchandiser | J16: E3 | K16: VN | S16: đã nghỉ việc | T16: Senior Executive
A17: Done | B17: =B16+1 -> 15 | D17: hieu.trantrung@mapactive.vn | I17: Business Development Manager | J17: E3 | K17: VN | S17: đã nghỉ việc | T17: Manager
A18: Need to keep until Ms Uyên Confirm | B18: =B17+1 -> 16 | D18: tri.dangquoc@mapactive.vn | I18: Retail Operations Manager | J18: E3 | K18: VN | S18: đã nghỉ việc | T18: Manager
A19: Can revoke license | B19: =B18+1 -> 17 | D19: hoang.phanbao@mapactive.vn | E19: Phan Bảo Hoàng | F19: Phan Bao Hoang | I19: Area Manager (South) | J19: E3 | K19: VN | S19: đã nghỉ việc | T19: Associate Manager
A20: Done | B20: =B19+1 -> 18 | D20: quynh.tranthilam@mapactive.vn | E20: Tran Thi Lâm Quỳnh | F20: Tran Thi lam Quynh | I20: Senior Merchandise | J20: E3 | K20: VN | S20: đã nghỉ việc | T20: Associate Manager
A21: Done | B21: =B20+1 -> 19 | D21: huong.tranquocthien@mapactive.vn | F21: Tran Quoc Thien Huong | I21: Senior Merchandise Planning Manager | J21: E3 | K21: VN | T21: Senior Manager
A22: Need to keep until Kelvin confirm (Oct-2023) | B22: =B21+1 -> 20 | D22: tien.phanthithuy@mapactive.vn | E22: Phan Thị Thủy Tiên | F22: Phan Thi Thuy Tiên | H22: Marketing | I22: Marketing officer | J22: E3 | K22: VN | M22: 8/5/2023 | N22: Done | O22: No need | P22: No need | S22: re-use Le Nguyen Trung Hau's Laptop
A23: done | B23: =B22+1 -> 21 | D23: vothea.iem@map.co.id | E23: Iem Vothea | F23: Iem Vothea | H23: Accounting | I23: Assistant Accountant Manager | J23: E3 | K23: KH | N23: Done | Q23: Done
A24: done | B24: =B23+1 -> 22 | D24: khoa.trandanganh@mapactive.vn | F24: Tran Dang Anh Khoa | I24: COE Officer | J24: E3 | K24: VN | T24: Associate
B25: 1 | D25: dung.phamthimy@mapactive.vn | E25: Phạm Thị Mỹ Dung | F25: Pham Thi My Dung | H25: Marketing Department | I25: Marketing Supervisor | J25: E3 | K25: VN | L25: `` | M25: 23/06/2023 | N25: Done | O25: Done | P25: 3520
A26: Done | B26: 2 | D26: ngan.huynhthibich@mpactive.vn | E26: Huỳnh Thị Bích Ngân | F26: Huynh Thi Bich Ngan | H26: Marketing Department | I26: Marketing Executive | J26: E3 | K26: VN | L26: Office | M26: 45270 | N26: Done | O26: No need | P26: x280 | R26: Done | S26: đã nghỉ việc 13/10/2023
A27: Waiting when HR Complete proccess resign | B27: 3 | C27: 22VN00000085 | D27: hieu.nguyenvutrung@mapactive.vn | E27: Nguyễn Vũ Trung Hiếu | F27: Nguyen Vu Trung Hieu | H27: Marketing Department | I27: Marketing Supervisor | J27: E3 | K27: VN | L27: Office | M27: 45140 | N27: Done | O27: Done | P27: 3520 | Q27: Done | R27: Done
A28: Done | B28: 4 | C28: 22VN00000047 | D28: dang.hohai@mapactive.vn | E28: Hồ Hải Đăng | F28: Ho Hai Dang | I28: Area Manager (South) | J28: E3 | K28: VN | L28: Office
A29: Done | B29: 5 | C29: 22VN00000075 | D29: quynh.phungnhu@mapactive.vn | E29: Phùng Như Quỳnh | F29: Phung Nhu Quynh | I29: Area Manager (North) | J29: E3 | K29: VN | L29: Office
A30: Need to keep until we have replacement | B30: 6 | C30: 22VN00000038 | D30: Trương Hồng Hương | E30: Truong Hong Huong | F30: Jolie | H30: Brand Manager (Birkenstock) | I30: E3 | J30: VN | K30: Office | S30: Senior Manager
A31: Done | B31: 7 | C31: 22VN00000086 | D31: quynh.nguyennhu@mapactive.vn | E31: Nguyễn Như Quỳnh | F31: Nguyen Nhu Quynh | H31: Brand Department | I31: Brand Manager (Bata) | J31: E3 | K31: VN | L31: Office | M31: 45152 | N31: Done | O31: Done | P31: 5430 | S31: BM for Bata, New Era
A32: Done | B32: 22 | C32: 22VN00000029 | D32: Tram.phamthibao@mapactive.vn | E32: Phạm Thị Bảo Trâm | F32: Pham Thi Bao Tram | I32: Marketing officer | J32: E3 | K32: VN | L32: Office | T32: Associate
B33: 11 | C33: 22VN00000026 | D33: dat.tranquoc@mapactive.vn | E33: Trần Quốc Đạt | F33: Tran Quoc Dat | I33: IT Officer | J33: E3 | K33: VN | L33: Office | T33: Senior Associate
A34: Done | C34: 22VN00000049 | D34: phong.phanhoai@mapactive.vn | E34: Phan Hoài Phong | F34: Phan Hoai Phong | H34: Marketing Department | I34: Visual Merchandise Executive | J34: E3 | K34: VN | L34: Office | M34: 45078 | N34: Done | O34: No need | P34: 3520
A35: Done | C35: 22VN00000068 | D35: my.tranthitoan@mapactive.vn | E35: Trần Thị Toàn Mỹ | F35: Tran Thi Toan My | I35: Senior Planning Merchandise | J35: E3 | K35: VN | L35: Office | M35: 45012 | N35: Done | O35: Done | P35: 3520 | Q35: Done | R35: Done
B36: =Office_Resigned!A57+1 -> 19 | C36: 22VN00000052 | D36: tra.truongvantin@mapactive.vn | E36: Trương Văn tín Trà | F36: Truong Van Tin Tra | I36: Project Supervisor | J36: E3 | K36: VN | L36: Office | T36: Senior Executive
B37: 32 | C37: 22VN00000040 | D37: tien.trantrung@mapactive.vn | E37: Trần Trung Tiến | F37: Tran Trung Tien | H37: Merchandise | I37: Senior Merchandise | J37: E3 | K37: VN | L37: Office | M37: 45012 | N37: Done | O37: No need | P37: 3520 | Q37: No need | R37: Done | S37: Replace Diệp team Ms. Jolie will resign on 10/04. Provide temporary MiniPC to use
B38: =Office_Resigned!A64+1 -> 20 | C38: 22VN00000009 | D38: hoa.mailecam@mapactive.vn | E38: Mai Lê Cẩm Hòa | F38: Mai Le Cam Hoa | G38: Mia | I38: Retail Admin Executive | J38: E3 | K38: VN | L38: Office | T38: Senior Executive
B39: =Office_Resigned!B45+1 -> #VALUE! | C39: 22VN00000094 | D39: minh.letranthien@mapactive.vn | E39: Lê Trần Thiên Minh | F39: Le Tran Thien Minh | H39: Operations Department | I39: Retail Operations Division Manager | J39: E3 | K39: VN | L39: Office | M39: 45136 | N39: Done | O39: Done | P39: 5430
B40: =VN_Emails!A26+1 -> 27 | C40: 22VN00000039 | D40: linh.thainhat@mapactive.vn | E40: Thái Nhật Linh | F40: Thai Nhat Linh | I40: Merchandiser | J40: E3 | K40: VN | L40: Office | T40: Senior Executive
B41: =Office_Resigned!A48+1 -> 21 | C41: 22VN00000062 | D41: loan.nguyenhoang@mapactive.vn | E41: Nguyễn Hoàng Loan | F41: Nguyen Hoang Loan | I41: Project Supervisor | J41: E3 | K41: VN | L41: Office | M41: 44984 | N41: Done | O41: Done | P41: 3520 | Q41: Done | R41: Done
...

Sheet Brand Code
A1: No. | B1: Brand Name | C1: Brand Code
A2: 1 | B2: Birkenstock | C2: BCK
A3: =A2+1 -> 2 | B3: Converse | C3: CON
A4: =A3+1 -> 3 | B4: Champion | C4: CMP
A5: =A4+1 -> 4 | B5: Foot Locker | C5: VO
A6: =A5+1 -> 5 | B6: New Balance | C6: NB
A7: =A6+1 -> 6 | B7: New Era | C7: NRA
A8: =A7+1 -> 7 | B8: Rookie | C8: HAD
A9: =A8+1 -> 8 | B9: Smiggle | C9: IGL
A10: =A9+1 -> 9 | B10: Planet Sports | C10: PS

Sheet Warehosue mail
A1: No | B1: Email Address | C1: Full Name | D1: Display Name | E1: Hostname | G1: No | H1: Email Address | I1: Full Name | J1: Display Name | K1: Hostname
A2: 1 | B2: vnwh.admininbound1@mapactive.vn | C2: vnwh.admininbound1 | D2: DSV - Admin (Inbound) 1 | E2: AMMAVNWHD000001 | G2: 1 | H2: Geodis.cs1@mapactive.vn | I2: Geodis.cs1 | J2: Geodis cs1
A3: 2 | B3: vnwh.adminoutbound1@mapactive.vn | C3: vnwh.adminoutbound1 | D3: DSV - Admin (Outbound) 1 | G3: 2 | H3: Geodis.cs2@mapactive.vn | I3: Geodis.cs2 | J3: Geodis cs2
A4: 3 | B4: vnwh.inventory1@mapactive.vn | C4: vnwh.inventory1 | D4: DSV - Admin (Inventory) 1 | G4: 3 | H4: Geodis.cs3@mapactive.vn | I4: Geodis.cs3 | J4: Geodis cs3
A5: 4 | B5: vnwh.management1@mapactive.vn | C5: vnwh.management1 | D5: DSV - Management 1 | E5: AMMAVNWHC000008 | G5: 4 | H5: Geodis.inbound1@mapactive.vn | I5: Geodis.inbound1 | J5: Geodis inbound1
A6: 5 | B6: vnwh.operation1@mapactive.vn | C6: vnwh.operation1 | D6: DSV - Operation 1 | G6: 5 | H6: Geodis.inbound2@mapactive.vn | I6: Geodis.inbound2 | J6: Geodis inbound2
A7: 6 | B7: vnwh.operation2@mapactive.vn | C7: vnwh.operation2 | D7: DSV - Operation 2 | G7: 6 | H7: Geodis.outobund1@mapactive.vn | I7: Geodis.outobund1 | J7: Geodis outbound1
A8: 7 | B8: vnwh.operation3@mapactive.vn | C8: vnwh.operation3 | D8: DSV - Operation 3 | G8: 7 | H8: Geodis.outbound2@mapactive.vn | I8: Geodis.outbound2 | J8: Geodis outbound2
A9: 8 | B9: vnwh.operation4@mapactive.vn | C9: vnwh.operation4 | D9: DSV - Operation 4
